Workbook

Sheet Feuile de Match
AQ2: FEDERATION FRANCAISE DE NATATION
B3: Équipe : | C3: Lion | S3: Bonnets | V3: B | Z3: RESULTAT FINAL | AD3: B | AE3: 7 | AH3: COMPETITION : | AK3: Championnat de France N3 Occitanie
AH4: LIEU : | AI4: ALBI | BB4: CHRONO GENERAL
B5: TEMPS MORT / PERIODE | I5: 1 | J5: 2 | K5: 3 | L5: 4 | AD5: N | AE5: 6 | AH5: DATE : | AI5: =TODAY() -> 46070 | AL5: HEURE: | AN5: 0.375 | AQ5: RAPPORT DE MATCH - WATERPOLO
B8: IUF | C8: NOMS - PRÉNOMS | P8: NAISS. | Q8: X | R8: N° | S8: BUTS | Z8: Code | AA8: Période | AB8: Code | AC8: Période | AD8: Code | AE8: Période | AH8: SECRETAIRE :……………………………… | AN8: IUF N°:……..…..….. | AQ8: CHRONO :………..…..……………………… | AW8: IUF N°:………..…..….. | BC8: 0
B9: =IF(C9="","",VLOOKUP(C9,'BD Joueurs Licence'!$B$3:$C$17,2)) -> 500 | C9: AE | P9: =IF(C9="","",VLOOKUP(C9,'BD Joueurs Licence'!$B$3:$D$17,3)) -> 1979 | R9: 1 | AH9: SECRETAIRE :……………………………… | AN9: IUF N°:…….…...….. | AQ9: 30' / 20' :……….….………………………… | AW9: IUF N°:…….…......…..
B10: =IF(C10="","",VLOOKUP(C10,'BD Joueurs Licence'!$B$3:$C$17,2)) -> 700 | C10: AG | P10: =IF(C10="","",VLOOKUP(C10,'BD Joueurs Licence'!$B$3:$D$17,3)) -> 1981 | R10: 2 | AH10: JUGE DE BUT :……………………………… | AN10: IUF N°:…….…...….. | AQ10: JUGE DE BUT :.…...………………………… | AW10: IUF N°:…….……...…..
B11: =IF(C11="","",VLOOKUP(C11,'BD Joueurs Licence'!$B$3:$C$17,2)) -> 800 | C11: AH | P11: =IF(C11="","",VLOOKUP(C11,'BD Joueurs Licence'!$B$3:$D$17,3)) -> 1982 | R11: 3
B12: =IF(C12="","",VLOOKUP(C12,'BD Joueurs Licence'!$B$3:$C$17,2)) -> 100 | C12: AA | P12: =IF(C12="","",VLOOKUP(C12,'BD Joueurs Licence'!$B$3:$D$17,3)) -> 1975 | R12: 4 | AH12: TEMPS | AI12: B | AJ12: N | AK12: CODE | AL12: SCORE | AN12: TEMPS | AO12: B | AP12: N | AQ12: CODE | AR12: SCORE | AT12: TEMPS | AU12: B | AV12: N | AW12: CODE | AX12: SCORE
B13: =IF(C13="","",VLOOKUP(C13,'BD Joueurs Licence'!$B$3:$C$17,2)) -> 1500 | C13: AO | P13: =IF(C13="","",VLOOKUP(C13,'BD Joueurs Licence'!$B$3:$D$17,3)) -> 1989 | R13: 5
B14: =IF(C14="","",VLOOKUP(C14,'BD Joueurs Licence'!$B$3:$C$17,2)) -> 1100 | C14: AK | P14: =IF(C14="","",VLOOKUP(C14,'BD Joueurs Licence'!$B$3:$D$17,3)) -> 1985 | R14: 6
B15: =IF(C15="","",VLOOKUP(C15,'BD Joueurs Licence'!$B$3:$C$17,2)) -> 300 | C15: AC | P15: =IF(C15="","",VLOOKUP(C15,'BD Joueurs Licence'!$B$3:$D$17,3)) -> 1977 | R15: 7
B16: =IF(C16="","",VLOOKUP(C16,'BD Joueurs Licence'!$B$3:$C$17,2)) -> 1400 | C16: AN | P16: =IF(C16="","",VLOOKUP(C16,'BD Joueurs Licence'!$B$3:$D$17,3)) -> 1988 | R16: 8
B17: =IF(C17="","",VLOOKUP(C17,'BD Joueurs Licence'!$B$3:$C$17,2)) -> 900 | C17: AI | P17: =IF(C17="","",VLOOKUP(C17,'BD Joueurs Licence'!$B$3:$D$17,3)) -> 1983 | R17: 9
B18: =IF(C18="","",VLOOKUP(C18,'BD Joueurs Licence'!$B$3:$C$17,2)) | P18: =IF(C18="","",VLOOKUP(C18,'BD Joueurs Licence'!$B$3:$D$17,3)) | R18: 10
B19: =IF(C19="","",VLOOKUP(C19,'BD Joueurs Licence'!$B$3:$C$17,2)) | P19: =IF(C19="","",VLOOKUP(C19,'BD Joueurs Licence'!$B$3:$D$17,3)) | R19: 11
B20: =IF(C20="","",VLOOKUP(C20,'BD Joueurs Licence'!$B$3:$C$17,2)) | P20: =IF(C20="","",VLOOKUP(C20,'BD Joueurs Licence'!$B$3:$D$17,3)) | R20: 12
B21: =IF(C21="","",VLOOKUP(C21,'BD Joueurs Licence'!$B$3:$C$17,2)) | P21: =IF(C21="","",VLOOKUP(C21,'BD Joueurs Licence'!$B$3:$D$17,3)) | R21: 13
B22: =IF(C22="","",VLOOKUP(C22,'BD Joueurs Licence'!$B$3:$C$17,2)) | P22: =IF(C22="","",VLOOKUP(C22,'BD Joueurs Licence'!$B$3:$D$17,3)) | R22: 14
B23: =IF(C23="","",VLOOKUP(C23,'BD Joueurs Licence'!$B$3:$C$17,2)) | P23: =IF(C23="","",VLOOKUP(C23,'BD Joueurs Licence'!$B$3:$D$17,3)) | R23: 15
Q24: ENTRAÎNEUR
Q25: ENTRAÎNEUR ADJOINT | Z25: RESULTATS | AD25: B | AE25: N
Q26: SUPPLÉANT | Z26: 1ère PERIODE
Z27: 2ème PERIODE
B29: Équipe : | C29: Aigle royal | S29: Bonnets | V29: N | Z29: 3ème PERIODE
Z30: 4ème PERIODE
B31: TEMPS MORT / PERIODE | I31: 1 | J31: 2 | K31: 3 | L31: 4 | Z31: PENALTY
B34: IUF | C34: NOMS - PRÉNOMS | P34: NAISS. | Q34: X | R34: N° | S34: BUTS | Z34: Code | AA34: Période | AB34: Code | AC34: Période | AD34: Code | AE34: Période
B35: =IF(C35="","",VLOOKUP(C35,'BD Joueurs Licence'!$E$3:$F$17,2)) -> 3000 | C35: BC | P35: =IF(C35="","",VLOOKUP(C35,'BD Joueurs Licence'!$E$3:$G$17,3)) -> 1992 | R35: 1
B36: =IF(C36="","",VLOOKUP(C36,'BD Joueurs Licence'!$E$3:$F$17,2)) -> 5000 | C36: BE | P36: =IF(C36="","",VLOOKUP(C36,'BD Joueurs Licence'!$E$3:$G$17,3)) -> 1994 | R36: 2
B37: =IF(C37="","",VLOOKUP(C37,'BD Joueurs Licence'!$E$3:$F$17,2)) -> 7000 | C37: BG | P37: =IF(C37="","",VLOOKUP(C37,'BD Joueurs Licence'!$E$3:$G$17,3)) -> 1996 | R37: 3
B38: =IF(C38="","",VLOOKUP(C38,'BD Joueurs Licence'!$E$3:$F$17,2)) -> 15000 | C38: BO | P38: =IF(C38="","",VLOOKUP(C38,'BD Joueurs Licence'!$E$3:$G$17,3)) -> 2004 | R38: 4
B39: =IF(C39="","",VLOOKUP(C39,'BD Joueurs Licence'!$E$3:$F$17,2)) -> 13000 | C39: BM | P39: =IF(C39="","",VLOOKUP(C39,'BD Joueurs Licence'!$E$3:$G$17,3)) -> 2002 | R39: 5
B40: =IF(C40="","",VLOOKUP(C40,'BD Joueurs Licence'!$E$3:$F$17,2)) -> 12000 | C40: BL | P40: =IF(C40="","",VLOOKUP(C40,'BD Joueurs Licence'!$E$3:$G$17,3)) -> 2001 | R40: 6 | AK40: NOMS - PRÉNOMS | AT40: IUF | AU40: SIGNATURE
B41: =IF(C41="","",VLOOKUP(C41,'BD Joueurs Licence'!$E$3:$F$17,2)) -> 9000 | C41: BI | P41: =IF(C41="","",VLOOKUP(C41,'BD Joueurs Licence'!$E$3:$G$17,3)) -> 1998 | R41: 7 | AH41: DÉLÉGUÉ BLANC
B42: =IF(C42="","",VLOOKUP(C42,'BD Joueurs Licence'!$E$3:$F$17,2)) -> 8000 | C42: BH | P42: =IF(C42="","",VLOOKUP(C42,'BD Joueurs Licence'!$E$3:$G$17,3)) -> 1997 | R42: 8 | AH42: DÉLÉGUÉ NOIR
B43: =IF(C43="","",VLOOKUP(C43,'BD Joueurs Licence'!$E$3:$F$17,2)) -> 14000 | C43: BN | P43: =IF(C43="","",VLOOKUP(C43,'BD Joueurs Licence'!$E$3:$G$17,3)) -> 2003 | R43: 9 | AH43: ARBITRE | AK43: RAJA
B44: =IF(C44="","",VLOOKUP(C44,'BD Joueurs Licence'!E12:F26,2)) | P44: =IF(C44="","",VLOOKUP(C44,'BD Joueurs Licence'!$E$3:$G$17,3)) | R44: 10 | AH44: ARBITRE
B45: =IF(C45="","",VLOOKUP(C45,'BD Joueurs Licence'!E13:F27,2)) | P45: =IF(C45="","",VLOOKUP(C45,'BD Joueurs Licence'!$E$3:$G$17,3)) | R45: 11 | AH45: DÉLÉGUÉ F.F.N.
B46: =IF(C46="","",VLOOKUP(C46,'BD Joueurs Licence'!E14:F28,2)) | P46: =IF(C46="","",VLOOKUP(C46,'BD Joueurs Licence'!$E$3:$G$17,3)) | R46: 12 | AH46: SIGNATURES DES DÉLÉGUÉS DES CLUBS (concernant les sanctions)
...

Sheet BD Joueurs Licence
B1: BLANCS | E1: NOIRS | I1: EQUIPES CHAMPIONNAT | K1: COMPETITION | M1: LIEU
B2: Nom Prénom | C2: Licence | D2: Naissance | E2: Nom Prénom | F2: Licence | G2: Naissance | I2: TARBES NAUTIC CLUB | K2: Championnat Régional Sénior | M2: TARBES
A3: 1 | B3: AA | C3: 100 | D3: 1975 | E3: BA | F3: 1000 | G3: 1990 | I3: Wolf | K3: Championnat de France N3 Occitanie | M3: TOULOUSE
A4: 2 | B4: AB | C4: 200 | D4: 1976 | E4: BB | F4: 2000 | G4: 1991 | I4: Lion | M4: PORTET-SUR-GARONNE
A5: 3 | B5: AC | C5: 300 | D5: 1977 | E5: BC | F5: 3000 | G5: 1992 | I5: CLUB NAUTIQUE PORTESIEN Equipe 1 | M5: MONTPELLIER
A6: 4 | B6: AD | C6: 400 | D6: 1978 | E6: BD | F6: 4000 | G6: 1993 | I6: MONTPELLIER U21 | M6: ALBI
A7: 5 | B7: AE | C7: 500 | D7: 1979 | E7: BE | F7: 5000 | G7: 1994 | I7: Aigle royal
A8: 6 | B8: AF | C8: 600 | D8: 1980 | E8: BF | F8: 6000 | G8: 1995 | I8: Team Panther
A9: 7 | B9: AG | C9: 700 | D9: 1981 | E9: BG | F9: 7000 | G9: 1996 | I9: SEA SUN POLO Equipe 2
A10: 8 | B10: AH | C10: 800 | D10: 1982 | E10: BH | F10: 8000 | G10: 1997
A11: 9 | B11: AI | C11: 900 | D11: 1983 | E11: BI | F11: 9000 | G11: 1998
A12: 10 | B12: AJ | C12: 1000 | D12: 1984 | E12: BJ | F12: 10000 | G12: 1999
A13: 11 | B13: AK | C13: 1100 | D13: 1985 | E13: BK | F13: 11000 | G13: 2000
A14: 12 | B14: AL | C14: 1200 | D14: 1986 | E14: BL | F14: 12000 | G14: 2001
A15: 13 | B15: AM | C15: 1300 | D15: 1987 | E15: BM | F15: 13000 | G15: 2002
A16: 14 | B16: AN | C16: 1400 | D16: 1988 | E16: BN | F16: 14000 | G16: 2003
A17: 15 | B17: AO | C17: 1500 | D17: 1989 | E17: BO | F17: 15000 | G17: 2004
